Workbook
Name Slicer_Region: #N/A

Sheet Instructions
A1: Advanced Excel – Job-Oriented Practice Workbook | B1: Complete practice workbook
A2: How to use | B2: Try every task yourself first. Use Solutions only for checking.
A3: Raw_Sales_Data | B3: 500 realistic sales records for formulas, filtering, PivotTables and dashboards.
A4: Employee_Data | B4: 100 employee records for HR calculations and analysis.
A5: Lookup_Master | B5: Product master for VLOOKUP, XLOOKUP and INDEX-MATCH.
A6: Formula_Practice | B6: 50 job-style tasks covering formulas and interview problems.
A7: Data_Cleaning | B7: Messy customer data for TRIM, CLEAN, text/number cleanup and duplicates.
A8: Pivot_Practice | B8: PivotTable tasks: region, category, month, salesperson and customer analysis.
A9: Dashboard_Data | B9: KPI calculations for a management dashboard.
A10: Dashboard | B10: One-page dashboard practice area.
A11: What_If | B11: Goal Seek and Scenario Manager practice cases.
A12: Solutions | B12: Common formula examples to compare with your work.
A14: Recommended Practice Method
A15: 1. First work on Raw_Sales_Data without looking at Formula_Bank.
A16: 2. Complete Detailed_Formula_Practice in order from Beginner → Intermediate → Advanced.
A17: 3. For lookup topics, use Lookup_Lab and test both valid and invalid product names.
A18: 4. For dates/text, use Date_Text_Lab and actually type formulas rather than reading them.
A19: 5. For PivotTable, create real PivotTables from Raw_Sales_Data and use grouping/slicers.
A20: 6. For Dashboard, build the visuals yourself; do not treat the Dashboard sheet as the final answer.
A21: 7. Finish Job_Interview_100 without looking at Formula_Bank. These are the closest tasks to job practice.
A22: 8. Only after attempting a task, check Formula_Bank.

Sheet Raw_Sales_Data
A1: Order_ID | B1: Order_Date | C1: Region | D1: State | E1: Salesperson | F1: Category | G1: Product | H1: Units | I1: Unit_Price | J1: Discount | K1: Revenue | L1: Cost | M1: Profit | N1: Customer_Type | O1: Payment_Mode
A2: ORD0001 | B2: 46004 | C2: West | D2: Maharashtra | E2: Priya | F2: Office Supplies | G2: Pen Set | H2: 4 | I2: 250 | J2: 0 | K2: 1000 | L2: 719.38838 | M2: 280.61162 | N2: Wholesale | O2: Bank Transfer
A3: ORD0002 | B3: 45945 | C3: West | D3: Maharashtra | E3: Sneha | F3: Electronics | G3: Monitor | H3: 4 | I3: 12000 | J3: 0.15 | K3: 40800 | L3: 33046.287 | M3: 7753.7132 | N3: Wholesale | O3: Bank Transfer
A4: ORD0003 | B4: 45832 | C4: South | D4: Tamil Nadu | E4: Neha | F4: Office Supplies | G4: Notebook | H4: 13 | I4: 120 | J4: 0 | K4: 1560 | L4: 1108.4924 | M4: 451.50759 | N4: Retail | O4: UPI
A5: ORD0004 | B5: 45967 | C5: North | D5: Delhi | E5: Neha | F5: Electronics | G5: Printer | H5: 2 | I5: 9000 | J5: 0.05 | K5: 17100 | L5: 13408.627 | M5: 3691.3733 | N5: Retail | O5: Bank Transfer
A6: ORD0005 | B6: 45843 | C6: West | D6: Gujarat | E6: Sneha | F6: Electronics | G6: Keyboard | H6: 14 | I6: 1800 | J6: 0.15 | K6: 21420 | L6: 18992.078 | M6: 2427.9217 | N6: Wholesale | O6: Cash
A7: ORD0006 | B7: 45852 | C7: West | D7: Goa | E7: Neha | F7: Furniture | G7: Bookshelf | H7: 2 | I7: 6500 | J7: 0 | K7: 13000 | L7: 9740.7862 | M7: 3259.2138 | N7: Corporate | O7: Card
A8: ORD0007 | B8: 46007 | C8: South | D8: Tamil Nadu | E8: Priya | F8: Office Supplies | G8: Pen Set | H8: 11 | I8: 250 | J8: 0.05 | K8: 2612.5 | L8: 1956.4013 | M8: 656.09865 | N8: Wholesale | O8: UPI
A9: ORD0008 | B9: 45824 | C9: South | D9: Karnataka | E9: Amit | F9: Accessories | G9: USB Hub | H9: 5 | I9: 1200 | J9: 0.15 | K9: 5100 | L9: 3603.0689 | M9: 1496.9311 | N9: Retail | O9: Cash
A10: ORD0009 | B10: 45819 | C10: North | D10: Rajasthan | E10: Sneha | F10: Office Supplies | G10: Notebook | H10: 4 | I10: 120 | J10: 0.15 | K10: 408 | L10: 360.75099 | M10: 47.249014 | N10: Wholesale | O10: Bank Transfer
A11: ORD0010 | B11: 45945 | C11: East | D11: Bihar | E11: Neha | F11: Accessories | G11: Headset | H11: 5 | I11: 2200 | J11: 0 | K11: 11000 | L11: 6673.9676 | M11: 4326.0324 | N11: Wholesale | O11: Bank Transfer
A12: ORD0011 | B12: 45682 | C12: East | D12: Odisha | E12: Priya | F12: Furniture | G12: Desk | H12: 9 | I12: 11000 | J12: 0.1 | K12: 89100 | L12: 56520.007 | M12: 32579.993 | N12: Retail | O12: UPI
A13: ORD0012 | B13: 45928 | C13: East | D13: Bihar | E13: Neha | F13: Electronics | G13: Printer | H13: 7 | I13: 9000 | J13: 0.15 | K13: 53550 | L13: 49083.799 | M13: 4466.2012 | N13: Wholesale | O13: Cash
... A501: ORD0500 | B501: 45849 | C501: East | D501: Bihar | E501: Rahul | F501: Furniture | G501: Cabinet | H501: 1 | I501: 8000 | J501: 0 | K501: 8000 | L501: 4767.4208 | M501: 3232.5792 | N501: Wholesale | O501: Cash

Sheet Detailed_Formula_Practice
A1: No. | B1: Level | C1: Topic | D1: Task / Business Question | E1: Use These Columns | F1: Expected Skill | G1: Your Formula / Answer
A2: 1 | B2: Beginner | C2: SUM | D2: Calculate total sales revenue | E2: Revenue | F2: SUM | G2: =SUM(SalesData[Revenue]) -> 24847359
A3: 2 | B3: Beginner | C3: AVERAGE | D3: Find average order revenue | E3: Revenue | F3: AVERAGE | G3: =AVERAGE(Raw_Sales_Data!K2:K501) -> 49694.718
A4: 3 | B4: Beginner | C4: MIN/MAX | D4: Find minimum and maximum order profit | E4: Profit | F4: MIN, MAX | G4: =MIN(SalesData[Profit]) -> 29.234866 | H4: =MAX(SalesData[Profit]) -> 255322.31
A5: 4 | B5: Beginner | C5: COUNT/COUNTA | D5: Count total orders and filled salesperson names | E5: Order_ID, Salesperson | F5: COUNT/COUNTA | G5: =COUNT(SalesData[Order_ID]) -> 0 | H5: =COUNTA(SalesData[Order_ID]) -> 500
A6: 5 | B6: Beginner | C6: ROUND | D6: Round revenue to nearest ₹100 | E6: Revenue | F6: ROUND
A7: 6 | B7: Beginner | C7: IF | D7: Show Profitable if Profit > 0, otherwise Loss | E7: Profit | F7: IF | G7: =IF(Raw_Sales_Data!M2>100,"Profit","Loss") -> Profit
A8: 7 | B8: Beginner | C8: AND | D8: Flag orders where Units > 10 AND Discount >= 10% | E8: Units, Discount | F8: AND + IF | G8: =IF(AND(Raw_Sales_Data!H2>10,Raw_Sales_Data!J2>10%),"Yes","No") -> No
A9: 8 | B9: Beginner | C9: OR | D9: Flag orders from West OR South | E9: Region | F9: OR + IF | G9: =IF(OR(Raw_Sales_Data!C2="West",Raw_Sales_Data!C2="south"),"Yes","No") -> Yes
A10: 9 | B10: Intermediate | C10: SUMIF | D10: Total revenue for West region | E10: Region, Revenue | F10: SUMIF | G10: =SUMIF(SalesData[Region],"West",SalesData[Revenue]) -> 7196940.5
A11: 10 | B11: Intermediate | C11: SUMIFS | D11: Revenue for West + Electronics | E11: Region, Category, Revenue | F11: SUMIFS | G11: =SUMIFS(SalesData[Revenue],SalesData[Region],"West",SalesData[Category],"Electronics") -> 4466780
A12: 11 | B12: Intermediate | C12: SUMIFS | D12: Profit for Corporate customers paid by UPI | E12: Customer_Type, Payment_Mode, Profit | F12: SUMIFS | G12: =SUMIFS(SalesData[Profit],SalesData[Customer_Type],"Corporate",SalesData[Payment_Mode],"UPI") -> 957574.75
A13: 12 | B13: Intermediate | C13: COUNTIF | D13: Count orders with 10% discount | E13: Discount | F13: COUNTIF | G13: =COUNTIF(Raw_Sales_Data!J481:J501,"10"%) -> 2
A14: 13 | B14: Intermediate | C14: COUNTIFS | D14: Count South + Corporate orders | E14: Region, Customer_Type | F14: COUNTIFS | G14: =COUNTIFS(SalesData[Region],"South",SalesData[Customer_Type],"Corporate") -> 37
A15: 14 | B15: Intermediate | C15: AVERAGEIF | D15: Average profit for Electronics | E15: Category, Profit | F15: AVERAGEIF | G15: =AVERAGEIF(SalesData[Category],"Electronics",SalesData[Profit]) -> 38119.557
A16: 15 | B16: Intermediate | C16: AVERAGEIFS | D16: Average revenue for West + Retail | E16: Region, Customer_Type, Revenue | F16: AVERAGEIFS | G16: =AVERAGEIFS(SalesData[Revenue],SalesData[Region],"West",SalesData[Customer_Type],"Retail") -> 55694.725
A17: 16 | B17: Intermediate | C17: IFERROR | D17: Return 0 instead of lookup error | E17: Product | F17: IFERROR
A18: 17 | B18: Intermediate | C18: Nested IF | D18: Create Low/Medium/High order-value band | E18: Revenue | F18: Nested IF
A19: 18 | B19: Intermediate | C19: IFS | D19: Classify profit: Loss / Low / Good / Excellent | E19: Profit | F19: IFS
A20: 19 | B20: Intermediate | C20: Text | D20: Extract first 3 characters of Order_ID | E20: Order_ID | F20: LEFT
A21: 20 | B21: Intermediate | C21: Text | D21: Extract last 2 characters of Order_ID | E21: Order_ID | F21: RIGHT
A22: 21 | B22: Intermediate | C22: Text | D22: Extract middle characters from Order_ID | E22: Order_ID | F22: MID
A23: 22 | B23: Intermediate | C23: Text | D23: Find position of '-' or a chosen character in text | E23: Text field | F23: FIND/SEARCH
A24: 23 | B24: Intermediate | C24: Text | D24: Remove extra spaces from customer text in Data_Cleaning | E24: Customer_Name | F24: TRIM
A25: 24 | B25: Intermediate | C25: Text | D25: Make emails lowercase | E25: Email | F25: LOWER
A26: 25 | B26: Intermediate | C26: Text | D26: Combine salesperson + region into one label | E26: Salesperson, Region | F26: CONCAT / &
A27: 26 | B27: Intermediate | C27: Date | D27: Extract year from Order_Date | E27: Order_Date | F27: YEAR
A28: 27 | B28: Intermediate | C28: Date | D28: Extract month number | E28: Order_Date | F28: MONTH
... A50: 49 | B50: Advanced | C50: Interview | D50: Find the region with the highest total profit | E50: Region + Profit | F50: Pivot/formula logic

Sheet Employee_Data
A1: Emp_ID | B1: Name | C1: Department | D1: Designation | E1: Joining_Date | F1: Location | G1: Salary | H1: Performance | I1: Experience_Years | J1: Manager
A2: E001 | B2: Meera | C2: HR | D2: Team Lead | E2: 43926 | F2: Pune | G2: 62707 | H2: Excellent | I2: 6 | J2: Akash
A3: E002 | B3: Riya | C3: Sales | D3: Senior Analyst | E3: 43921 | F3: Nashik | G3: 68499 | H3: Good | I3: 6 | J3: Aditya
A4: E003 | B4: Manish | C4: Operations | D4: Senior Analyst | E4: 44300 | F4: Delhi | G4: 43526 | H4: Excellent | I4: 5 | J4: Varun
A5: E004 | B5: Meera | C5: Finance | D5: Analyst | E5: 45853 | F5: Nashik | G5: 62226 | H5: Good | I5: 1 | J5: Manish
A6: E005 | B6: Om | C6: Marketing | D6: Executive | E6: 43683 | F6: Nashik | G6: 75940 | H6: Average | I6: 7 | J6: Tanya
A7: E006 | B7: Arjun | C7: Finance | D7: Manager | E7: 43907 | F7: Bengaluru | G7: 55299 | H7: Needs Improvement | I7: 6 | J7: Isha
A8: E007 | B8: Ananya | C8: Operations | D8: Team Lead | E8: 44758 | F8: Nashik | G8: 49434 | H8: Good | I8: 4 | J8: Om
A9: E008 | B9: Arjun | C9: IT | D9: Analyst | E9: 45762 | F9: Delhi | G9: 64967 | H9: Average | I9: 1 | J9: Ananya
A10: E009 | B10: Nikita | C10: IT | D10: Developer | E10: 45077 | F10: Mumbai | G10: 71580 | H10: Average | I10: 3 | J10: Kavya
A11: E010 | B11: Manish | C11: IT | D11: Manager | E11: 45519 | F11: Mumbai | G11: 75747 | H11: Excellent | I11: 2 | J11: Manish
A12: E011 | B12: Sahil | C12: Finance | D12: Senior Analyst | E12: 44389 | F12: Pune | G12: 36507 | H12: Needs Improvement | I12: 5 | J12: Kavya
A13: E012 | B13: Kavya | C13: Operations | D13: Analyst | E13: 45175 | F13: Bengaluru | G13: 65944 | H13: Average | I13: 3 | J13: Om
... A101: E100 | B101: Karan | C101: HR | D101: Team Lead | E101: 44870 | F101: Pune | G101: 90004 | H101: Needs Improvement | I101: 4 | J101: Varun

Sheet Lookup_Master
A1: Product | B1: Category | C1: Standard_Price | D1: Target_Margin | E1: Region_Manager
A2: Laptop | B2: Electronics | C2: 55000 | D2: 0.2 | E2: Ramesh
A3: Monitor | B3: Electronics | C3: 12000 | D3: 0.2 | E3: Swati
A4: Keyboard | B4: Electronics | C4: 1800 | D4: 0.25 | E4: Mahesh
A5: Printer | B5: Electronics | C5: 9000 | D5: 0.25 | E5: Mahesh
A6: Office Chair | B6: Furniture | C6: 7000 | D6: 0.15 | E6: Swati
A7: Desk | B7: Furniture | C7: 11000 | D7: 0.3 | E7: Ramesh
A8: Bookshelf | B8: Furniture | C8: 6500 | D8: 0.3 | E8: Deepak
A9: Cabinet | B9: Furniture | C9: 8000 | D9: 0.3 | E9: Swati
A10: Notebook | B10: Office Supplies | C10: 120 | D10: 0.3 | E10: Ramesh
A11: Pen Set | B11: Office Supplies | C11: 250 | D11: 0.3 | E11: Deepak
A12: File Folder | B12: Office Supplies | C12: 80 | D12: 0.2 | E12: Ramesh
A13: Stapler | B13: Office Supplies | C13: 180 | D13: 0.15 | E13: Deepak
... A17: USB Hub | B17: Accessories | C17: 1200 | D17: 0.3 | E17: Deepak

Sheet Data_Cleaning
A1: Customer_Name | B1: City | C1: Phone | D1: Email | E1: Product | F1: Amount | H1: Cleaning Tasks
A2: Rahul Patil | B2: nashik | C2: 98765 43210 | D2: rahul@EXAMPLE.com | E2: Laptop | F2: 55000 | G2: =TRIM(A2) -> Rahul Patil | H2: TRIM names
A3: Priya Shah | B3: PUNE | C3: 9876543210 | D3: priya@example.com | E3: Monitor | F3: 12000 | G3: =PROPER(B3) -> Pune | H3: Standardize City
A4: Amit Joshi | B4: Mumbai | C4: 98765-11111 | D4: amit@example.com | E4: Laptop | F4: 55000 | G4: =SUBSTITUTE(C4,"-","") -> 9876511111 | H4: Clean phone numbers
A5: Sneha Patil | B5: nashik | C5: 98765 22222 | D5: sneha@Example.COM | E5: Mouse | F5: 900 | G5: =LOWER(D5) -> sneha@example.com | H5: Lowercase emails
A6: Karan More | B6: Pune | C6: 9876512345 | D6: karan@example.com | E6: Keyboard | F6: 1800 | G6: =TRIM(E6) -> Keyboard | H6: TRIM products
A7: Riya Kulkarni | B7: MUMBAI | C7: 98765-44444 | D7: riya@example.com | E7: Printer | F7: 9000 | G7: =VALUE(F7) -> 9000 | H7: Convert Amount to number
A8: Rahul Patil | B8: Nashik | C8: 9876543210 | D8: rahul@example.com | E8: Laptop | F8: 55000 | H8: Remove duplicates
A9: Neha Shinde | B9: pune | C9: 98765 66666 | D9: neha@example.com | E9: Monitor | F9: 12000 | H9: Create cleaned table

Sheet Dashboard_Data
A1: KPI | B1: Formula
A2: Total Revenue | B2: =SUM(Raw_Sales_Data!K2:K501) -> 24847359
A3: Total Cost | B3: =SUM(Raw_Sales_Data!L2:L501) -> 17413156
A4: Total Profit | B4: =SUM(Raw_Sales_Data!M2:M501) -> 7434203.1
A5: Profit Margin | B5: =B4/B2 -> 0.2991949
A6: Total Orders | B6: =COUNTA(Raw_Sales_Data!A2:A501) -> 500
A7: Average Order Value | B7: =B2/B6 -> 49694.718

Sheet Dashboard
S1: Row Labels | T1: Sum of Revenue
S2: East | T2: 6903819.5
S3: North | T3: 7049343.5
S4: South | T4: 3697255.5
S5: West | T5: 7196940.5
S6: Grand Total | T6: 24847359
S8: Row Labels | T8: Sum of Profit
S9: Accessories | T9: 580255.93
S10: Electronics | T10: 4459988.1
S11: Furniture | T11: 2353780
S12: Office Supplies | T12: 40179.001
S13: Grand Total | T13: 7434203.1
S15: Row Labels | T15: Sum of Revenue
S16: Jan | T16: 2524922
S17: Feb | T17: 1249596
S18: Mar | T18: 2533755
S19: Apr | T19: 1409463
S20: May | T20: 1586837
S21: Jun | T21: 2248515
S22: Jul | T22: 2709489.5
S23: Aug | T23: 2872099
S24: Sep | T24: 2012981.5
S25: Oct | T25: 2822996
S26: Nov | T26: 1869562
S27: Dec | T27: 1007143
S28: Grand Total | T28: 24847359
S30: Row Labels | T30: Sum of Revenue
S31: Corporate | T31: 7694756
S32: Retail | T32: 7113981.5
S33: Wholesale | T33: 10038622
S34: Grand Total | T34: 24847359
S36: Row Labels | T36: Sum of Revenue
S37: Cabinet | T37: 2137600
S38: Desk | T38: 2286350
S39: Laptop | T39: 10032000
S40: Monitor | T40: 2310000
S41: Printer | T41: 2191950
S42: Grand Total | T42: 18957900
S44: Row Labels
S45: East
...

Sheet What_If
A1: Case | B1: Input | C1: Value
A2: Current Units | B2: Units | C2: 100
A3: Current Price | B3: Price | C3: 500
A4: Current Cost/Unit | B4: Cost | C4: 320
A5: Current Revenue | B5: Revenue | C5: =C2*C3 -> 50000
A6: Current Profit | B6: Profit | C6: =C5-(C2*C4) -> 18000
A7: Goal | B7: Target Profit | C7: 25000
A8: Practice | B8: Goal Seek | C8: Change Units until Profit = Target Profit
A9: Scenario 1 | B9: Price +10%
A10: Scenario 2 | B10: Cost -8%
A11: Scenario 3 | B11: Units +20%
A12: Practice | B12: Scenario Manager | C12: Create Current / Best / Worst

Sheet Lookup_Lab
A1: No. | B1: Challenge | C1: Source | D1: Target | E1: Hint | F1: Your Formula | G1: Result | H1: Test Product
H2: Laptop
A3: 1 | B3: XLOOKUP basic | C3: Enter a product name and return Category | D3: Lookup_Master | E3: Category | F3: Exact match
A4: 2 | B4: XLOOKUP price | C4: Return Standard Price | D4: Lookup_Master | E4: Standard_Price | F4: Exact match
A5: 3 | B5: XLOOKUP manager | C5: Return Region Manager | D5: Lookup_Master | E5: Region_Manager | F5: Exact match
A6: 4 | B6: XLOOKUP missing | C6: Try a fake product and display Not Found | D6: Lookup_Master | E6: Category | F6: IFNA/IFERROR
A7: 5 | B7: VLOOKUP basic | C7: Return Category from product | D7: Lookup_Master | E7: Category | F7: FALSE exact match
A8: 6 | B8: VLOOKUP price | C8: Return Standard Price | D8: Lookup_Master | E8: Standard_Price | F8: Column index
A9: 7 | B9: INDEX MATCH | C9: Return Target Margin | D9: Lookup_Master | E9: Target_Margin | F9: MATCH product, INDEX margin
A10: 8 | B10: INDEX MATCH | C10: Return manager | D10: Lookup_Master | E10: Region_Manager | F10: Two ranges
A11: 9 | B11: Two-condition lookup | C11: Return a value based on Product + Category | D11: Lookup_Master | E11: Any field | F11: Use concatenation/helper or XLOOKUP
A12: 10 | B12: Reverse lookup | C12: Given manager, return a product | D12: Lookup_Master | E12: Product | F12: INDEX/MATCH or XLOOKUP
A13: 11 | B13: Lookup from sales | C13: Add Category to a new mini order table using Product | D13: Raw_Sales_Data | E13: Category | F13: XLOOKUP
A14: 12 | B14: Lookup from sales | C14: Add standard price beside sales price | D14: Raw_Sales_Data | E14: Standard_Price | F14: XLOOKUP
... A17: 15 | B17: Interview | C17: Which product has highest standard price? | D17: Lookup_Master | E17: Product | F17: MAX + XLOOKUP

Sheet Date_Text_Lab
A1: No. | B1: Topic | C1: Task | D1: Example Input | E1: Expected Output / Goal | F1: Your Formula | G1: Result
A2: 1 | B2: Date | C2: Extract day | D2: 15-Apr-2025 | E2: 15 | F2: =TEXT(D2,"dd") -> 15
A3: 2 | B3: Date | C3: Extract month | D3: 15-Apr-2025 | E3: 4 | F3: =TEXT(D3,"mm") -> 04
A4: 3 | B4: Date | C4: Extract year | D4: 15-Apr-2025 | E4: 2025 | F4: =TEXT(D4,"yyyy") -> 2025
A5: 4 | B5: Date | C5: Month name | D5: 15-Apr-2025 | E5: April | F5: =TEXT(D5,"mmmm") -> April
A6: 5 | B6: Date | C6: Short month | D6: 15-Apr-2025 | E6: Apr | F6: =TEXT(D6,"mmm") -> Apr
A7: 6 | B7: Date | C7: Quarter | D7: 15-Apr-2025 | E7: Q1
A8: 7 | B8: Date | C8: Financial Year Apr-Mar | D8: 15-Apr-2025 | E8: FY 2025-26
A9: 8 | B9: Date | C9: End of month | D9: 15-Apr-2025 | E9: 30-Apr-2025 | F9: =D9+15 -> 45777
A10: 9 | B10: Date | C10: Start of month | D10: 15-Apr-2025 | E10: 01-Apr-2025 | F10: =D10-14 -> 45748
A11: 10 | B11: Date | C11: Days elapsed | D11: 15-Apr-2025 | E11: Today - date | F11: =TODAY() -> 46277
A12: 11 | B12: Date | C12: Weekday name | D12: 15-Apr-2025 | E12: Tuesday | F12: =TEXT(D12,"dddd") -> Tuesday
A13: 12 | B13: Date | C13: Weekend flag | D13: Any date | E13: Weekend/Weekday
A14: 13 | B14: Text | C14: First name | D14: Lokesh Ahire | E14: Lokesh | F14: =LEFT(D14,6) -> Lokesh
A15: 14 | B15: Text | C15: Last name | D15: Lokesh Ahire | E15: Ahire | F15: =RIGHT(D15,5) -> Ahire
A16: 15 | B16: Text | C16: Name length | D16: Lokesh Ahire | E16: 11 | F16: =LEN(TRIM(D16)) -> 12
A17: 16 | B17: Text | C17: Uppercase | D17: Lokesh Ahire | E17: LOKESH AHIRE | F17: =UPPER(D17) -> LOKESH AHIRE
A18: 17 | B18: Text | C18: Lowercase | D18: LOKESH AHIRE | E18: lokesh ahire | F18: =LOWER(D18) -> lokesh ahire
A19: 18 | B19: Text | C19: Proper case | D19: lOKESH aHIRE | E19: Lokesh Ahire | F19: =PROPER(D19) -> Lokesh Ahire
A20: 19 | B20: Text | C20: Trim spaces | D20: Lokesh Ahire | E20: Lokesh Ahire | F20: =TRIM(D20) -> Lokesh Ahire
A21: 20 | B21: Text | C21: Replace spaces | D21: Lokesh Ahire | E21: Lokesh_Ahire | F21: =REPLACE(D21,7,1,"_") -> Lokesh_Ahire
A22: 21 | B22: Text | C22: Join fields | D22: Lokesh + Nashik | E22: Lokesh - Nashik | F22: =SUBSTITUTE(D22,"+","-") -> Lokesh - Nashik
A23: 22 | B23: Text | C23: Find character | D23: rahul@example.com | E23: position of @
A24: 23 | B24: Text | C24: Extract email domain | D24: rahul@example.com | E24: example.com | F24: =RIGHT(D24,11) -> example.com
A25: 24 | B25: Text | C25: Extract email username | D25: rahul@example.com | E25: rahul | F25: =LEFT(D25,5) -> rahul
A26: 25 | B26: Text | C26: Clean phone | D26: 98765-43210 | E26: 9876543210 | F26: =SUBSTITUTE(D26,"-","") -> 9876543210

Sheet Conditional_Format_Lab
A1: No. | B1: Rule | C1: Range | D1: What to do | E1: Expected visual
A2: 1 | B2: 1 | C2: Revenue > ₹50,000 | D2: Raw_Sales_Data Revenue | E2: Highlight high-value orders | F2: Clearly visible
A3: 2 | B3: 2 | C3: Profit < 0 | D3: Raw_Sales_Data Profit | E3: Highlight loss orders | F3: Clearly visible
A4: 3 | B4: 3 | C4: Discount >= 10% | D4: Raw_Sales_Data Discount | E4: Highlight heavy discounts | F4: Clearly visible
A5: 4 | B5: 4 | C5: Top 10 Revenue | D5: Revenue column | E5: Top 10 rule | F5: Top performers
A6: 5 | B6: 5 | C6: Bottom 10 Profit | D6: Profit column | E6: Bottom 10 rule | F6: Weak performers
A7: 6 | B7: 6 | C7: Duplicate Order_ID | D7: Order_ID column | E7: Duplicate values rule | F7: Duplicates
A8: 7 | B8: 7 | C8: Data bars | D8: Revenue column | E8: Add data bars | F8: Size comparison
A9: 8 | B9: 8 | C9: Color scale | D9: Profit column | E9: 3-color scale | F9: Low to high
A10: 9 | B10: 9 | C10: Formula rule | D10: Entire sales row | E10: Revenue > average revenue | F10: Highlight entire row
A11: 10 | B11: 10 | C11: Weekend dates | D11: Order_Date | E11: Use WEEKDAY formula | F11: Weekend rows
A12: 11 | B12: 11 | C12: Above target | D12: Create target column first | E12: Actual > Target | F12: Positive variance
A13: 12 | B13: 12 | C13: Below target | D13: Create target column first | E13: Actual < Target | F13: Negative variance

Sheet Data_Cleaning_Lab
A1: No. | B1: Cleaning Task | C1: Why it matters | D1: Tool/Function | E1: Do it on Data_Cleaning sheet | F1: Status
A2: 1 | B2: 1 | C2: Remove leading/trailing spaces | D2: Prevents lookup mismatch | E2: TRIM | F2: Customer_Name
A3: 2 | B3: 2 | C3: Fix multiple spaces | D3: Standardize names | E3: TRIM | F3: Customer_Name
A4: 3 | B4: 3 | C4: Standardize city names | D4: Consistent reporting | E4: PROPER/UPPER | F4: City
A5: 4 | B5: 4 | C5: Clean phone numbers | D5: Remove spaces and hyphens | E5: SUBSTITUTE | F5: Phone
A6: 5 | B6: 5 | C6: Lowercase emails | D6: Consistent email data | E6: LOWER | F6: Email
A7: 6 | B7: 6 | C7: Convert amount from text to number | D7: Enables calculations | E7: VALUE / multiply by 1 | F7: Amount
A8: 7 | B8: 7 | C8: Remove duplicate customer records | D8: Avoid double counting | E8: Remove Duplicates | F8: Whole table
A9: 8 | B9: 8 | C9: Find blank cells | D9: Data completeness | E9: Go To Special / Filter | F9: Whole table
A10: 9 | B10: 9 | C10: Find inconsistent product names | D10: Lookup consistency | E10: TRIM + compare | F10: Product
A11: 10 | B11: 10 | C11: Create a clean final table | D11: Reusable dataset | E11: Excel Table | F11: All cleaned columns
A12: 11 | B12: 11 | C12: Sort highest amount | D12: Analysis preparation | E12: Sort | F12: Amount
A13: 12 | B13: 12 | C13: Filter Nashik customers | D13: Quick analysis | E13: Filter | F13: City

Sheet Pivot_Masterclass
A1: No. | B1: Scenario | C1: Rows | D1: Columns | E1: Values | F1: Filters/Slicers | G1: Extra Practice
A2: 1 | B2: 1 | C2: Revenue by Region | D2: Region | F2: Sum Revenue | H2: Sort largest to smallest
A3: 2 | B3: 2 | C3: Profit by Category | D3: Category | F3: Sum Profit | H3: Show values as currency
A4: 3 | B4: 3 | C4: Monthly Revenue | D4: Order_Date | F4: Sum Revenue | H4: Group by Months
A5: 4 | B5: 4 | C5: Monthly Revenue by Region | D5: Order_Date | E5: Region | F5: Sum Revenue | H5: Group date by Months
A6: 5 | B6: 5 | C6: Salesperson Performance | D6: Salesperson | F6: Sum Revenue, Sum Profit | H6: Add Profit Margin calculated field if available
A7: 6 | B7: 6 | C7: Customer Type | D7: Customer_Type | F7: Sum Revenue, Count Order_ID | H7: Compare Retail/Corporate/Wholesale
A8: 7 | B8: 7 | C8: Payment Mode | D8: Payment_Mode | F8: Sum Revenue | H8: Add percentage of grand total
A9: 8 | B9: 8 | C9: Top Products | D9: Product | F9: Sum Revenue | H9: Sort descending; show Top 10
A10: 9 | B10: 9 | C10: Region × Category | D10: Region | E10: Category | F10: Sum Revenue | H10: Heatmap with conditional formatting
A11: 10 | B11: 10 | C11: Profit by State | D11: State | F11: Sum Profit | H11: Top 5 states
A12: 11 | B12: 11 | C12: Discount Analysis | D12: Discount | F12: Sum Revenue, Sum Profit | H12: Group discount levels
A13: 12 | B13: 12 | C13: Manager MIS | D13: Salesperson | F13: Revenue, Profit, Units | H13: Add Region filter
A14: 13 | B14: 13 | C14: Dashboard Pivot | D14: Month | E14: Region | F14: Revenue | H14: Add slicers
A15: 14 | B15: 14 | C15: Interview | D15: Salesperson | F15: Revenue | H15: Who is #1?
A16: 15 | B16: 15 | C16: Interview | D16: Region | F16: Profit | H16: Which region needs attention?

Sheet Dashboard_Project
A1: Step | B1: Requirement | C1: Data Source | D1: What you must build | E1: Done?
A2: 1 | B2: 1 | C2: Total Revenue KPI | D2: Raw_Sales_Data | E2: Card
A3: 2 | B3: 2 | C3: Total Profit KPI | D3: Raw_Sales_Data | E3: Card
A4: 3 | B4: 3 | C4: Profit Margin KPI | D4: Raw_Sales_Data | E4: Card
A5: 4 | B5: 4 | C5: Total Orders KPI | D5: Raw_Sales_Data | E5: Card
A6: 5 | B6: 5 | C6: Average Order Value | D6: Raw_Sales_Data | E6: Card
A7: 6 | B7: 6 | C7: Revenue by Region | D7: Pivot | E7: Column/Bar chart
A8: 7 | B8: 7 | C8: Profit by Category | D8: Pivot | E8: Bar chart
A9: 8 | B9: 8 | C9: Monthly Revenue Trend | D9: Pivot | E9: Line chart
A10: 9 | B10: 9 | C10: Top 5 Products | D10: Pivot | E10: Bar chart
A11: 10 | B11: 10 | C11: Customer Type Revenue | D11: Pivot | E11: Doughnut/Column chart
A12: 11 | B12: 11 | C12: Region filter | D12: Pivot | E12: Slicer
A13: 12 | B13: 12 | C13: Category filter | D13: Pivot | E13: Slicer
... A16: 15 | B16: 15 | C16: Final test | D16: All | E16: Filter slicers and verify KPIs update

Sheet Job_Interview_100
A1: No. | B1: Category | C1: Interview / Practical Question | D1: Your Answer / Formula | E1: Difficulty
A2: 1 | B2: Formula | C2: Total Revenue | E2: Easy
A3: 2 | B3: Formula | C3: Total Profit | E3: Easy
A4: 3 | B4: Formula | C4: Average Order Value | E4: Easy
A5: 4 | B5: Formula | C5: Highest Revenue Order | E5: Easy
A6: 5 | B6: Formula | C6: Lowest Profit Order | E6: Easy
A7: 6 | B7: Formula | C7: Count Corporate Orders | E7: Easy
A8: 7 | B8: Formula | C8: Count UPI Orders | E8: Easy
A9: 8 | B9: Formula | C9: Revenue from West | E9: Easy
A10: 9 | B10: Formula | C10: Profit from Electronics | E10: Easy
A11: 10 | B11: Formula | C11: Average Revenue for Retail | E11: Easy
A12: 11 | B12: Formula | C12: Orders with discount >=10% | E12: Easy
A13: 12 | B13: Formula | C13: Orders with revenue > average | E13: Easy
... A84: 83 | B84: Final | C84: One-page Sales MIS | E84: Hard

Sheet Formula_Bank
A1: Topic | B1: Formula | C1: What it does | D1: Example / Note
A2: SUM | B2: =SUM(K2:K501) -> 0 | C2: Adds revenue | D2: Total revenue
A3: AVERAGE | B3: =AVERAGE(K2:K501) -> #DIV/0! | C3: Average revenue | D3: Average order value if one row = one order
A4: COUNT | B4: =COUNT(H2:H501) -> 0 | C4: Counts numbers | D4: Units
A5: COUNTA | B5: =COUNTA(A2:A501) -> 37 | C5: Counts nonblank cells | D5: Orders
A6: IF | B6: =IF(M2>0,"Profitable","Loss") -> Loss | C6: Condition | D6: Profit status
A7: AND | B7: =IF(AND(H2>10,J2>=10%),"Flag","OK") -> OK | C7: Multiple conditions | D7: Both must be true
A8: OR | B8: =IF(OR(C2="West",C2="South"),"Flag","OK") -> OK | C8: Either condition | D8: At least one true
A9: SUMIF | B9: =SUMIF(C:C,"West",K:K) -> 0 | C9: One condition | D9: West revenue
A10: SUMIFS | B10: =SUMIFS(K:K,C:C,"West",F:F,"Electronics") -> 0 | C10: Multiple conditions | D10: West Electronics revenue
A11: COUNTIF | B11: =COUNTIF(J:J,">=10%") -> 0 | C11: Count one condition | D11: High discount orders
A12: COUNTIFS | B12: =COUNTIFS(C:C,"South",N:N,"Corporate") -> 0 | C12: Count multiple conditions | D12: South corporate
A13: AVERAGEIF | B13: =AVERAGEIF(F:F,"Electronics",M:M) -> #DIV/0! | C13: Average with one condition | D13: Electronics profit
A14: AVERAGEIFS | B14: =AVERAGEIFS(K:K,C:C,"West",N:N,"Retail") -> #DIV/0! | C14: Average with multiple conditions | D14: West retail revenue
A15: XLOOKUP | B15: =_xludf.XLOOKUP(G2,Lookup_Master!A:A,Lookup_Master!B:B,"Not Found") -> #NAME? | C15: Modern lookup | D15: Product → Category
A16: VLOOKUP | B16: =VLOOKUP(G2,Lookup_Master!A:E,3,FALSE) -> #N/A | C16: Classic lookup | D16: Product → Price
A17: INDEX MATCH | B17: =INDEX(Lookup_Master!D:D,MATCH(G2,Lookup_Master!A:A,0)) -> #N/A | C17: Flexible lookup | D17: Product → Margin
A18: IFERROR | B18: =IFERROR(_xludf.XLOOKUP(G2,Lookup_Master!A:A,Lookup_Master!C:C),0) -> 0 | C18: Handles errors | D18: Returns 0 if missing
A19: YEAR | B19: =YEAR(B2) -> 1900 | C19: Year from date | D19: 2025
A20: MONTH | B20: =MONTH(B2) -> 1 | C20: Month number | D20: 4
A21: TEXT | B21: =TEXT(B2,"mmmm") -> January | C21: Month name | D21: April
A22: Quarter | B22: ="Q"&ROUNDUP(MONTH(B2)/3,0) -> Q1 | C22: Quarter | D22: Q1–Q4
A23: Financial Year | B23: ="FY "&IF(MONTH(B2)>=4,YEAR(B2)&"-"&RIGHT(YEAR(B2)+1,2),(YEAR(B2)-1)&"-"&RIGHT(YEAR(B2),2)) -> FY 1899-00 | C23: Apr-Mar FY | D23: FY 2025-26
A24: TODAY | B24: =TODAY()-B2 -> 46277 | C24: Days elapsed | D24: Dynamic
A25: LEFT | B25: =LEFT(A2,3) -> SUM | C25: Left characters | D25: ORD
A26: RIGHT | B26: =RIGHT(A2,2) -> UM | C26: Right characters | D26: Last 2
A27: MID | B27: =MID(A2,4,3) | C27: Middle characters | D27: Based on position
A28: TRIM | B28: =TRIM(A2) -> SUM | C28: Removes extra spaces | D28: Data cleaning
A29: LOWER | B29: =LOWER(D2) -> total revenue | C29: Lowercase | D29: Emails
A30: UPPER | B30: =UPPER(E2) | C30: Uppercase | D30: Names
A31: PROPER | B31: =PROPER(A2) -> Sum | C31: Proper case | D31: Names
A32: CONCAT | B32: =E2&" - "&C2 -> - Adds revenue | C32: Combines fields | D32: Salesperson - Region
A33: SUMPRODUCT | B33: =SUMPRODUCT(H2:H501,I2:I501*(1-J2:J501)) -> 0 | C33: Array-style calculation | D33: Revenue after discount
A34: SUBTOTAL | B34: =SUBTOTAL(9,K2:K501) -> 0 | C34: Works with filtered rows | D34: Visible revenue
A35: UNIQUE | B35: =_xludf.UNIQUE(E2:E501) -> #NAME? | C35: Unique list | D35: Salespeople
A36: FILTER | C36: Dynamic filter | D36: Electronics orders
A37: SORTBY | B37: =_xludf.SORTBY(Lookup_Master!A2:E17,Lookup_Master!C2:C17,-1) -> #NAME? | C37: Sort dynamic range | D37: Price descending
A38: Contribution | B38: =K2/SUM($K$2:$K$501) -> #DIV/0! | C38: Share of total | D38: Format as %
